Workbook

Sheet 1_Inputs
A1: AGENTLY — Unit Economics & Pricing Model
A2: Every number below is either MEASURED (from the live code or database), SOURCED (published third-party figure, cited), or ASSUMPTION (a placeholder that must be replaced with a real measurement). Blue = you can change it. Yellow fill = assumption, replace as soon as real data exists. Every other sheet reads from this one — change a value here and the whole model updates.
A3: Built 10 Sep 2026 · v1
A6: A. WHAT A HOSTED CALL ACTUALLY COSTS US
A7: Variable | B7: Value | C7: Unit | D7: Status | E7: Source / why this number
A8: LLM the invoke route calls | B8: claude-sonnet-5 | C8: model | D8: MEASURED | E8: app/api/hosted-agents/[slug]/invoke/route.ts:258 — read from the live code, not assumed.
A9: Input price per 1M tokens (USD) | B9: 2 | C9: USD | D9: SOURCED | E9: Anthropic published API pricing for claude-sonnet-5. Verify at anthropic.com/pricing before investor use.
A10: Output price per 1M tokens (USD) | B10: 10 | C10: USD | D10: SOURCED | E10: Anthropic published API pricing for claude-sonnet-5. Verify at anthropic.com/pricing before investor use.
A11: USD → EUR conversion rate | B11: 0.92 | C11: EUR per USD | D11: ASSUMPTION | E11: Placeholder. Replace with the rate your Stripe/bank actually settles at.
A12: max_tokens cap per call | B12: 2048 | C12: tokens | D12: MEASURED | E12: app/api/hosted-agents/[slug]/invoke/route.ts:259 — hard ceiling on output per call.
A13: Average INPUT tokens per call | B13: 1500 | C13: tokens | D13: ASSUMPTION | E13: Hidden agent system prompt + user input. NOT measured — log real token counts from the Anthropic response usage object and replace this. This is the single most important number in the model.
A14: Average OUTPUT tokens per call | B14: 600 | C14: tokens | D14: ASSUMPTION | E14: Assumed well below the 2048 cap. NOT measured — same fix as above: log response.usage.output_tokens.
A15: Non-LLM infra cost per call (Vercel, Supabase) | B15: 0.0002 | C15: EUR | D15: ASSUMPTION | E15: Serverless function + DB writes per invocation. Small but non-zero. Replace with real Vercel/Supabase billing divided by call count once there is volume.
A17: B. WHAT WE CHARGE — CURRENT LIVE PRICING
A18: Variable | B18: Value | C18: Unit | D18: Status | E18: Source / why this number
A19: Basic tier — monthly price | B19: 9 | C19: EUR | D19: MEASURED | E19: lib/membership.ts MEMBERSHIP_TIERS.basic.monthlyPriceCents = 900. Code comment calls it a placeholder.
A20: Basic tier — monthly credits granted | B20: 300 | C20: credits | D20: MEASURED | E20: lib/membership.ts. Code comment: 'Round, clearly-arbitrary numbers... not measured against any real per-call cost.' This model exists to fix exactly that.
A21: Pro tier — monthly price | B21: 29 | C21: EUR | D21: MEASURED | E21: lib/membership.ts monthlyPriceCents = 2900.
A22: Pro tier — monthly credits granted | B22: 1500 | C22: credits | D22: MEASURED | E22: lib/membership.ts.
A23: Professional tier — monthly price | B23: 99 | C23: EUR | D23: MEASURED | E23: lib/membership.ts monthlyPriceCents = 9900.
A24: Professional tier — monthly credits granted | B24: 8000 | C24: credits | D24: MEASURED | E24: lib/membership.ts.
A25: Credits charged per call (creator-set) | B25: 1 | C25: credits | D25: ASSUMPTION | E25: Each creator sets credits_per_call on their agent, capped at 50 (lib/hosted-agents.ts MAX_CREDITS_PER_CALL). 1 = the cheapest case, i.e. the worst case for us. Change to test other settings.
A26: Free credits granted at signup (one-time) | B26: 20 | C26: credits | D26: MEASURED | E26: One-time non-renewing grant. Pure marketing cost — no revenue behind it.
A28: C. HOW REVENUE IS SPLIT
A29: Variable | B29: Value | C29: Unit | D29: Status | E29: Source / why this number
A30: Platform fee — share WE keep | B30: 0.15 | C30: % of revenue | D30: MEASURED | E30: lib/membership.ts PLATFORM_FEE_PERCENT = 15. Report ch.6: 'start low (10-15%), raise once there's liquidity.'
A31: Creator share — share THEY get | B31: 0.85 | C31: % of revenue | D31: MEASURED | E31: =1 − platform fee. lib/creator-payouts.ts pools 85% of membership revenue and splits it by usage share.
A32: Creator payout is calculated on… | B32: GROSS revenue | C32: basis | D32: MEASURED | E32: lib/creator-payouts.ts: poolCents = totalRevenueCents × 85%. API cost is NOT deducted first. See sheet 4 — this is the structural problem.
A34: D. PAYMENT PROCESSING
A35: Variable | B35: Value | C35: Unit | D35: Status | E35: Source / why this number
A36: Stripe percentage fee (EU cards) | B36: 0.015 | C36: % of charge | D36: SOURCED | E36: Stripe published EU standard rate ~1.5%. Verify against your own Stripe dashboard.
A37: Stripe fixed fee per charge | B37: 0.25 | C37: EUR | D37: MEASURED | E37: lib/membership.ts comment: measured at ~€0.25-0.30 by running a live €1 test purchase and reading the resulting Stripe balance transactions — platform ended at -€0.13 net on it.
A39: E. GROWTH ASSUMPTIONS (sheet 5 only — all unproven)
A40: Variable | B40: Value | C40: Unit | D40: Status | E40: Source / why this number
A41: Paying members at month 0 | B41: 2 | C41: members | D41: MEASURED | E41: Live Supabase query 6.9.2026 — and both are David's own test accounts, not external customers.
A42: New free signups per month | B42: 40 | C42: signups | D42: ASSUMPTION | E42: No basis in real data. There are 3 registered users total today. Placeholder to make the sheet compute.
A43: Free → paid conversion rate | B43: 0.04 | C43: % | D43: ASSUMPTION | E43: Typical prosumer SaaS freemium conversion is low single digits. Not measured for this product.
A44: Monthly churn of paying members | B44: 0.07 | C44: % | D44: ASSUMPTION | E44: Placeholder in the normal SMB/prosumer range. Not measured — there is no cohort history yet.
A45: Tier mix — Basic | B45: 0.6 | C45: % of paid | D45: ASSUMPTION | E45: Placeholder. No real mix data exists.
A46: Tier mix — Pro | B46: 0.3 | C46: % of paid | D46: ASSUMPTION | E46: Placeholder.
...

Sheet 2_Cost per Call
A1: COST PER CALL — the bill of materials, in tokens
A2: Béroche's BOM sheet costs a bottle, a pump and a label. Ours costs input tokens, output tokens and serverless compute. Same idea: you cannot price a product until you know what one unit costs to produce. The model column shows what the same call would cost on a cheaper Claude model — that is a real lever.
A4: PER-CALL COST BY MODEL CHOICE
A5: Model | B5: Input $/1M | C5: Output $/1M | D5: Input cost (€) | E5: Output cost (€) | F5: Total per call (€) | G5: Note
A6: claude-sonnet-5 ← what we run today | B6: 2 | C6: 10 | D6: =('1_Inputs'!$B$13/1000000)*B6*'1_Inputs'!$B$11 | E6: =('1_Inputs'!$B$14/1000000)*C6*'1_Inputs'!$B$11 | F6: =D6+E6+'1_Inputs'!$B$15 | G6: Currently hardcoded in the invoke route. Source: Anthropic published pricing.
A7: claude-haiku-4-5 | B7: 1 | C7: 5 | D7: =('1_Inputs'!$B$13/1000000)*B7*'1_Inputs'!$B$11 | E7: =('1_Inputs'!$B$14/1000000)*C7*'1_Inputs'!$B$11 | F7: =D7+E7+'1_Inputs'!$B$15 | G7: Half the price of Sonnet 5. Viable for simple prompt-based agents (category 1) — a real cost lever.
A8: claude-opus-5 | B8: 5 | C8: 25 | D8: =('1_Inputs'!$B$13/1000000)*B8*'1_Inputs'!$B$11 | E8: =('1_Inputs'!$B$14/1000000)*C8*'1_Inputs'!$B$11 | F8: =D8+E8+'1_Inputs'!$B$15 | G8: 2.5× Sonnet 5. Only justified for agents where output quality is the product.
A10: SENSITIVITY — what if the token estimate is wrong?
A11: The two token counts on sheet 1 are assumptions, not measurements. This grid shows the cost per call across a realistic range so you can see how much the answer moves. Read the row that matches your guess; the model uses the sheet-1 values.
A13: Input tokens ↓ / Output tokens → | B13: 300 | C13: 600 | D13: 1,000 | E13: 1,500 | F13: 2,048 (cap)
A14: 500 input tokens | B14: =(500/1000000)*'1_Inputs'!$B$9*'1_Inputs'!$B$11+(300/1000000)*'1_Inputs'!$B$10*'1_Inputs'!$B$11+'1_Inputs'!$B$15 | C14: =(500/1000000)*'1_Inputs'!$B$9*'1_Inputs'!$B$11+(600/1000000)*'1_Inputs'!$B$10*'1_Inputs'!$B$11+'1_Inputs'!$B$15 | D14: =(500/1000000)*'1_Inputs'!$B$9*'1_Inputs'!$B$11+(1000/1000000)*'1_Inputs'!$B$10*'1_Inputs'!$B$11+'1_Inputs'!$B$15 | E14: =(500/1000000)*'1_Inputs'!$B$9*'1_Inputs'!$B$11+(1500/1000000)*'1_Inputs'!$B$10*'1_Inputs'!$B$11+'1_Inputs'!$B$15 | F14: =(500/1000000)*'1_Inputs'!$B$9*'1_Inputs'!$B$11+(2048/1000000)*'1_Inputs'!$B$10*'1_Inputs'!$B$11+'1_Inputs'!$B$15
A15: 1,000 input tokens | B15: =(1000/1000000)*'1_Inputs'!$B$9*'1_Inputs'!$B$11+(300/1000000)*'1_Inputs'!$B$10*'1_Inputs'!$B$11+'1_Inputs'!$B$15 | C15: =(1000/1000000)*'1_Inputs'!$B$9*'1_Inputs'!$B$11+(600/1000000)*'1_Inputs'!$B$10*'1_Inputs'!$B$11+'1_Inputs'!$B$15 | D15: =(1000/1000000)*'1_Inputs'!$B$9*'1_Inputs'!$B$11+(1000/1000000)*'1_Inputs'!$B$10*'1_Inputs'!$B$11+'1_Inputs'!$B$15 | E15: =(1000/1000000)*'1_Inputs'!$B$9*'1_Inputs'!$B$11+(1500/1000000)*'1_Inputs'!$B$10*'1_Inputs'!$B$11+'1_Inputs'!$B$15 | F15: =(1000/1000000)*'1_Inputs'!$B$9*'1_Inputs'!$B$11+(2048/1000000)*'1_Inputs'!$B$10*'1_Inputs'!$B$11+'1_Inputs'!$B$15
A16: 1,500 input tokens | B16: =(1500/1000000)*'1_Inputs'!$B$9*'1_Inputs'!$B$11+(300/1000000)*'1_Inputs'!$B$10*'1_Inputs'!$B$11+'1_Inputs'!$B$15 | C16: =(1500/1000000)*'1_Inputs'!$B$9*'1_Inputs'!$B$11+(600/1000000)*'1_Inputs'!$B$10*'1_Inputs'!$B$11+'1_Inputs'!$B$15 | D16: =(1500/1000000)*'1_Inputs'!$B$9*'1_Inputs'!$B$11+(1000/1000000)*'1_Inputs'!$B$10*'1_Inputs'!$B$11+'1_Inputs'!$B$15 | E16: =(1500/1000000)*'1_Inputs'!$B$9*'1_Inputs'!$B$11+(1500/1000000)*'1_Inputs'!$B$10*'1_Inputs'!$B$11+'1_Inputs'!$B$15 | F16: =(1500/1000000)*'1_Inputs'!$B$9*'1_Inputs'!$B$11+(2048/1000000)*'1_Inputs'!$B$10*'1_Inputs'!$B$11+'1_Inputs'!$B$15
A17: 2,500 input tokens | B17: =(2500/1000000)*'1_Inputs'!$B$9*'1_Inputs'!$B$11+(300/1000000)*'1_Inputs'!$B$10*'1_Inputs'!$B$11+'1_Inputs'!$B$15 | C17: =(2500/1000000)*'1_Inputs'!$B$9*'1_Inputs'!$B$11+(600/1000000)*'1_Inputs'!$B$10*'1_Inputs'!$B$11+'1_Inputs'!$B$15 | D17: =(2500/1000000)*'1_Inputs'!$B$9*'1_Inputs'!$B$11+(1000/1000000)*'1_Inputs'!$B$10*'1_Inputs'!$B$11+'1_Inputs'!$B$15 | E17: =(2500/1000000)*'1_Inputs'!$B$9*'1_Inputs'!$B$11+(1500/1000000)*'1_Inputs'!$B$10*'1_Inputs'!$B$11+'1_Inputs'!$B$15 | F17: =(2500/1000000)*'1_Inputs'!$B$9*'1_Inputs'!$B$11+(2048/1000000)*'1_Inputs'!$B$10*'1_Inputs'!$B$11+'1_Inputs'!$B$15
A18: 4,000 input tokens | B18: =(4000/1000000)*'1_Inputs'!$B$9*'1_Inputs'!$B$11+(300/1000000)*'1_Inputs'!$B$10*'1_Inputs'!$B$11+'1_Inputs'!$B$15 | C18: =(4000/1000000)*'1_Inputs'!$B$9*'1_Inputs'!$B$11+(600/1000000)*'1_Inputs'!$B$10*'1_Inputs'!$B$11+'1_Inputs'!$B$15 | D18: =(4000/1000000)*'1_Inputs'!$B$9*'1_Inputs'!$B$11+(1000/1000000)*'1_Inputs'!$B$10*'1_Inputs'!$B$11+'1_Inputs'!$B$15 | E18: =(4000/1000000)*'1_Inputs'!$B$9*'1_Inputs'!$B$11+(1500/1000000)*'1_Inputs'!$B$10*'1_Inputs'!$B$11+'1_Inputs'!$B$15 | F18: =(4000/1000000)*'1_Inputs'!$B$9*'1_Inputs'!$B$11+(2048/1000000)*'1_Inputs'!$B$10*'1_Inputs'!$B$11+'1_Inputs'!$B$15
A20: Yellow cell = the combination the model currently assumes. Across this whole grid the cost per call stays between roughly €0.002 and €0.030 — so even the optimistic corner does not rescue the tier economics on sheet 3.

Sheet 3_Tier Margins
A1: TIER MARGINS — does each membership actually make money?
A2: For each tier: what we charge, what we owe the creator (85% of GROSS revenue, per lib/creator-payouts.ts), what Stripe takes, and what the API calls cost us. Columns are credit utilisation — the share of the granted monthly credits a member actually uses. The break-even row is the punchline.
A4: BASIC — see sheet 1 for price and credit allotment
A5: Metric | B5: 10% used | C5: 25% used | D5: 50% used | E5: 75% used | F5: 100% used
A6: Credits actually used | B6: ='1_Inputs'!$B$20*0.1 | C6: ='1_Inputs'!$B$20*0.25 | D6: ='1_Inputs'!$B$20*0.5 | E6: ='1_Inputs'!$B$20*0.75 | F6: ='1_Inputs'!$B$20*1.0
A7: Calls that represents | B7: ='1_Inputs'!$B$20*0.1/'1_Inputs'!$B$25 | C7: ='1_Inputs'!$B$20*0.25/'1_Inputs'!$B$25 | D7: ='1_Inputs'!$B$20*0.5/'1_Inputs'!$B$25 | E7: ='1_Inputs'!$B$20*0.75/'1_Inputs'!$B$25 | F7: ='1_Inputs'!$B$20*1.0/'1_Inputs'!$B$25
A8: Gross revenue (member pays) | B8: ='1_Inputs'!$B$19 | C8: ='1_Inputs'!$B$19 | D8: ='1_Inputs'!$B$19 | E8: ='1_Inputs'!$B$19 | F8: ='1_Inputs'!$B$19
A9: less: creator payout (85% of gross) | B9: =-'1_Inputs'!$B$19*'1_Inputs'!$B$31 | C9: =-'1_Inputs'!$B$19*'1_Inputs'!$B$31 | D9: =-'1_Inputs'!$B$19*'1_Inputs'!$B$31 | E9: =-'1_Inputs'!$B$19*'1_Inputs'!$B$31 | F9: =-'1_Inputs'!$B$19*'1_Inputs'!$B$31
A10: less: Stripe processing fee | B10: =-('1_Inputs'!$B$19*'1_Inputs'!$B$36+'1_Inputs'!$B$37) | C10: =-('1_Inputs'!$B$19*'1_Inputs'!$B$36+'1_Inputs'!$B$37) | D10: =-('1_Inputs'!$B$19*'1_Inputs'!$B$36+'1_Inputs'!$B$37) | E10: =-('1_Inputs'!$B$19*'1_Inputs'!$B$36+'1_Inputs'!$B$37) | F10: =-('1_Inputs'!$B$19*'1_Inputs'!$B$36+'1_Inputs'!$B$37)
A11: less: API + infra cost | B11: =-'1_Inputs'!$B$20*0.1*'1_Inputs'!$B$56 | C11: =-'1_Inputs'!$B$20*0.25*'1_Inputs'!$B$56 | D11: =-'1_Inputs'!$B$20*0.5*'1_Inputs'!$B$56 | E11: =-'1_Inputs'!$B$20*0.75*'1_Inputs'!$B$56 | F11: =-'1_Inputs'!$B$20*1.0*'1_Inputs'!$B$56
A12: =PLATFORM NET PER MEMBER / MONTH | B12: =SUM(B8:B11) | C12: =SUM(C8:C11) | D12: =SUM(D8:D11) | E12: =SUM(E8:E11) | F12: =SUM(F8:F11)
A13: Net margin % of revenue | B13: =IFERROR(B12/'1_Inputs'!$B$19,0) | C13: =IFERROR(C12/'1_Inputs'!$B$19,0) | D13: =IFERROR(D12/'1_Inputs'!$B$19,0) | E13: =IFERROR(E12/'1_Inputs'!$B$19,0) | F13: =IFERROR(F12/'1_Inputs'!$B$19,0)
A14: BREAK-EVEN utilisation (above this, we lose money) | B14: =IFERROR(('1_Inputs'!$B$19*(1-'1_Inputs'!$B$31)-('1_Inputs'!$B$19*'1_Inputs'!$B$36+'1_Inputs'!$B$37))/('1_Inputs'!$B$20*'1_Inputs'!$B$56),0) | C14: ← what we keep after creator + Stripe, divided by the cost of using every granted credit
A17: PRO — see sheet 1 for price and credit allotment
A18: Metric | B18: 10% used | C18: 25% used | D18: 50% used | E18: 75% used | F18: 100% used
A19: Credits actually used | B19: ='1_Inputs'!$B$22*0.1 | C19: ='1_Inputs'!$B$22*0.25 | D19: ='1_Inputs'!$B$22*0.5 | E19: ='1_Inputs'!$B$22*0.75 | F19: ='1_Inputs'!$B$22*1.0
A20: Calls that represents | B20: ='1_Inputs'!$B$22*0.1/'1_Inputs'!$B$25 | C20: ='1_Inputs'!$B$22*0.25/'1_Inputs'!$B$25 | D20: ='1_Inputs'!$B$22*0.5/'1_Inputs'!$B$25 | E20: ='1_Inputs'!$B$22*0.75/'1_Inputs'!$B$25 | F20: ='1_Inputs'!$B$22*1.0/'1_Inputs'!$B$25
A21: Gross revenue (member pays) | B21: ='1_Inputs'!$B$21 | C21: ='1_Inputs'!$B$21 | D21: ='1_Inputs'!$B$21 | E21: ='1_Inputs'!$B$21 | F21: ='1_Inputs'!$B$21
A22: less: creator payout (85% of gross) | B22: =-'1_Inputs'!$B$21*'1_Inputs'!$B$31 | C22: =-'1_Inputs'!$B$21*'1_Inputs'!$B$31 | D22: =-'1_Inputs'!$B$21*'1_Inputs'!$B$31 | E22: =-'1_Inputs'!$B$21*'1_Inputs'!$B$31 | F22: =-'1_Inputs'!$B$21*'1_Inputs'!$B$31
A23: less: Stripe processing fee | B23: =-('1_Inputs'!$B$21*'1_Inputs'!$B$36+'1_Inputs'!$B$37) | C23: =-('1_Inputs'!$B$21*'1_Inputs'!$B$36+'1_Inputs'!$B$37) | D23: =-('1_Inputs'!$B$21*'1_Inputs'!$B$36+'1_Inputs'!$B$37) | E23: =-('1_Inputs'!$B$21*'1_Inputs'!$B$36+'1_Inputs'!$B$37) | F23: =-('1_Inputs'!$B$21*'1_Inputs'!$B$36+'1_Inputs'!$B$37)
A24: less: API + infra cost | B24: =-'1_Inputs'!$B$22*0.1*'1_Inputs'!$B$56 | C24: =-'1_Inputs'!$B$22*0.25*'1_Inputs'!$B$56 | D24: =-'1_Inputs'!$B$22*0.5*'1_Inputs'!$B$56 | E24: =-'1_Inputs'!$B$22*0.75*'1_Inputs'!$B$56 | F24: =-'1_Inputs'!$B$22*1.0*'1_Inputs'!$B$56
A25: =PLATFORM NET PER MEMBER / MONTH | B25: =SUM(B21:B24) | C25: =SUM(C21:C24) | D25: =SUM(D21:D24) | E25: =SUM(E21:E24) | F25: =SUM(F21:F24)
A26: Net margin % of revenue | B26: =IFERROR(B25/'1_Inputs'!$B$21,0) | C26: =IFERROR(C25/'1_Inputs'!$B$21,0) | D26: =IFERROR(D25/'1_Inputs'!$B$21,0) | E26: =IFERROR(E25/'1_Inputs'!$B$21,0) | F26: =IFERROR(F25/'1_Inputs'!$B$21,0)
A27: BREAK-EVEN utilisation (above this, we lose money) | B27: =IFERROR(('1_Inputs'!$B$21*(1-'1_Inputs'!$B$31)-('1_Inputs'!$B$21*'1_Inputs'!$B$36+'1_Inputs'!$B$37))/('1_Inputs'!$B$22*'1_Inputs'!$B$56),0) | C27: ← what we keep after creator + Stripe, divided by the cost of using every granted credit
A30: PROFESSIONAL — see sheet 1 for price and credit allotment
A31: Metric | B31: 10% used | C31: 25% used | D31: 50% used | E31: 75% used | F31: 100% used
A32: Credits actually used | B32: ='1_Inputs'!$B$24*0.1 | C32: ='1_Inputs'!$B$24*0.25 | D32: ='1_Inputs'!$B$24*0.5 | E32: ='1_Inputs'!$B$24*0.75 | F32: ='1_Inputs'!$B$24*1.0
A33: Calls that represents | B33: ='1_Inputs'!$B$24*0.1/'1_Inputs'!$B$25 | C33: ='1_Inputs'!$B$24*0.25/'1_Inputs'!$B$25 | D33: ='1_Inputs'!$B$24*0.5/'1_Inputs'!$B$25 | E33: ='1_Inputs'!$B$24*0.75/'1_Inputs'!$B$25 | F33: ='1_Inputs'!$B$24*1.0/'1_Inputs'!$B$25
A34: Gross revenue (member pays) | B34: ='1_Inputs'!$B$23 | C34: ='1_Inputs'!$B$23 | D34: ='1_Inputs'!$B$23 | E34: ='1_Inputs'!$B$23 | F34: ='1_Inputs'!$B$23
A35: less: creator payout (85% of gross) | B35: =-'1_Inputs'!$B$23*'1_Inputs'!$B$31 | C35: =-'1_Inputs'!$B$23*'1_Inputs'!$B$31 | D35: =-'1_Inputs'!$B$23*'1_Inputs'!$B$31 | E35: =-'1_Inputs'!$B$23*'1_Inputs'!$B$31 | F35: =-'1_Inputs'!$B$23*'1_Inputs'!$B$31
A36: less: Stripe processing fee | B36: =-('1_Inputs'!$B$23*'1_Inputs'!$B$36+'1_Inputs'!$B$37) | C36: =-('1_Inputs'!$B$23*'1_Inputs'!$B$36+'1_Inputs'!$B$37) | D36: =-('1_Inputs'!$B$23*'1_Inputs'!$B$36+'1_Inputs'!$B$37) | E36: =-('1_Inputs'!$B$23*'1_Inputs'!$B$36+'1_Inputs'!$B$37) | F36: =-('1_Inputs'!$B$23*'1_Inputs'!$B$36+'1_Inputs'!$B$37)
A37: less: API + infra cost | B37: =-'1_Inputs'!$B$24*0.1*'1_Inputs'!$B$56 | C37: =-'1_Inputs'!$B$24*0.25*'1_Inputs'!$B$56 | D37: =-'1_Inputs'!$B$24*0.5*'1_Inputs'!$B$56 | E37: =-'1_Inputs'!$B$24*0.75*'1_Inputs'!$B$56 | F37: =-'1_Inputs'!$B$24*1.0*'1_Inputs'!$B$56
A38: =PLATFORM NET PER MEMBER / MONTH | B38: =SUM(B34:B37) | C38: =SUM(C34:C37) | D38: =SUM(D34:D37) | E38: =SUM(E34:E37) | F38: =SUM(F34:F37)
A39: Net margin % of revenue | B39: =IFERROR(B38/'1_Inputs'!$B$23,0) | C39: =IFERROR(C38/'1_Inputs'!$B$23,0) | D39: =IFERROR(D38/'1_Inputs'!$B$23,0) | E39: =IFERROR(E38/'1_Inputs'!$B$23,0) | F39: =IFERROR(F38/'1_Inputs'!$B$23,0)
A40: BREAK-EVEN utilisation (above this, we lose money) | B40: =IFERROR(('1_Inputs'!$B$23*(1-'1_Inputs'!$B$31)-('1_Inputs'!$B$23*'1_Inputs'!$B$36+'1_Inputs'!$B$37))/('1_Inputs'!$B$24*'1_Inputs'!$B$56),0) | C40: ← what we keep after creator + Stripe, divided by the cost of using every granted credit
A43: WHAT THIS SHEET SAYS
A44: The platform keeps only 15% of membership revenue, but pays 100% of the API cost out of that 15%. So the break-even is not a matter of scale or efficiency — it is arithmetic: API cost must stay under 15% of revenue, minus Stripe. The higher the tier, the more credits are granted per euro, and therefore the WORSE the economics. That is the opposite of how tiers are supposed to work: normally the expensive tier is the profitable one. Note also what is NOT on this sheet: any cost for the free 20-credit signup grant, support time, or David's own time. Those only make it worse. Sheet 4 works out what would have to change.

Sheet 4_Credit Pricing
A1: WHAT A CREDIT MUST COST — and the two ways to fix the split
A2: Sheet 3 shows the current pricing loses money. This sheet works out by how much, and prices the two structural fixes. Everything here is arithmetic off sheet 1 — no new assumptions are introduced.
A4: A. WHAT WE SELL A CREDIT FOR TODAY, VS WHAT IT COSTS
A5: Tier | B5: Price per credit charged | C5: Cost per credit | D5: Sold at … × cost | E5: Verdict
A6: Basic | B6: ='1_Inputs'!$B$19/'1_Inputs'!$B$20 | C6: ='1_Inputs'!$B$56 | D6: =IFERROR(B6/C6,0) | E6: Must exceed cost ÷ 15% to survive — see section B. A multiple below that is a structural loss, not a volume problem.
A7: Pro | B7: ='1_Inputs'!$B$21/'1_Inputs'!$B$22 | C7: ='1_Inputs'!$B$56 | D7: =IFERROR(B7/C7,0) | E7: Must exceed cost ÷ 15% to survive — see section B. A multiple below that is a structural loss, not a volume problem.
A8: Professional | B8: ='1_Inputs'!$B$23/'1_Inputs'!$B$24 | C8: ='1_Inputs'!$B$56 | D8: =IFERROR(B8/C8,0) | E8: Must exceed cost ÷ 15% to survive — see section B. A multiple below that is a structural loss, not a volume problem.
A10: B. THE MINIMUM VIABLE CREDIT PRICE, UNDER THE CURRENT 85/15 SPLIT
A11: Calculation | B11: Value | E11: Explanation
A12: Cost per credit | B12: ='1_Inputs'!$B$56 | E12: From sheet 1 — what one credit of usage costs us in API + infra.
A13: Share of revenue we keep (platform fee) | B13: ='1_Inputs'!$B$30 | E13: The creator takes the other 85%, calculated on GROSS revenue before any cost is deducted.
A14: less: Stripe's percentage fee | B14: ='1_Inputs'!$B$36 | E14: Comes out of our share too. The fixed €0.25 per charge is handled per-tier on sheet 3, since it does not scale with credits.
A15: MINIMUM price per credit to break even | B15: =IFERROR('1_Inputs'!$B$56/('1_Inputs'!$B$30-'1_Inputs'!$B$36),0) | E15: cost ÷ (15% platform fee − 1.5% Stripe) = cost ÷ 13.5%. Below this price, what we keep cannot cover the API bill, at any volume. Scale does not help: the gap widens with every extra call.
A16: Professional tier sells credits at | B16: ='1_Inputs'!$B$23/'1_Inputs'!$B$24 | E16: €99 ÷ 8,000 credits — the cheapest credit we sell, and therefore the worst case.
A17: Shortfall — how far under the minimum | B17: =IFERROR(B15/B16,0) | E17: How many times over the current Professional credit price would have to rise, with nothing else changed.
A19: C. THE TWO STRUCTURAL FIXES, PRICED
A20: Option | B20: Platform net per €100 of revenue | C20: Creator gets | D20: Feasible? | E20: What it means in practice
A21: Today — creators paid 85% of GROSS revenue | B21: =100*'1_Inputs'!$B$30-((100/('1_Inputs'!$B$23/'1_Inputs'!$B$24))*'1_Inputs'!$B$48*'1_Inputs'!$B$56)-(100*'1_Inputs'!$B$36) | C21: =100*'1_Inputs'!$B$31 | D21: NO | E21: What the code does today (lib/creator-payouts.ts). We pay the API bill out of our 15%. Negative above the break-even utilisation on sheet 3.
A22: Fix 1 — creators paid 85% of NET revenue (after API cost) | B22: =(100-((100/('1_Inputs'!$B$23/'1_Inputs'!$B$24))*'1_Inputs'!$B$48*'1_Inputs'!$B$56)-(100*'1_Inputs'!$B$36))*'1_Inputs'!$B$30 | C22: =(100-((100/('1_Inputs'!$B$23/'1_Inputs'!$B$24))*'1_Inputs'!$B$48*'1_Inputs'!$B$56)-(100*'1_Inputs'!$B$36))*'1_Inputs'!$B$31 | D22: YES | E22: Deduct the API cost of serving the calls before splitting. Cannot go negative, at any utilisation. This is a one-line change in the payout formula and the single highest-leverage fix in this model.
A23: Fix 2 — keep 85% of gross, but reprice credits to the sheet-4B minimum | B23: =100*'1_Inputs'!$B$30-(100/(IFERROR('1_Inputs'!$B$56/('1_Inputs'!$B$30-'1_Inputs'!$B$36),1)))*'1_Inputs'!$B$48*'1_Inputs'!$B$56-(100*'1_Inputs'!$B$36) | C23: =100*'1_Inputs'!$B$31 | D23: YES, but | E23: Keeps the marketing-friendly 85/15 headline, but a Professional membership would buy roughly a fifth of the credits it does today. Harder to sell, and it prices out exactly the heavy users a marketplace needs.
A26: Recommendation: Fix 1. Paying creators a share of net rather than gross is what every marketplace with real per-transaction costs does — the 85/15 App Store analogy breaks precisely because Apple has no per-download compute bill. It keeps the creator's incentive identical (they still earn more when their agent is used more), it cannot produce a negative month, and it survives a heavy user. Fix 2 is a fallback if the 85% headline turns out to matter for recruiting creators — but it should be tested, not assumed.

Sheet 5_Projection 36M
A1: 36-MONTH PROJECTION — scaffolding, not a forecast
A2: EVERY growth input behind this sheet is an assumption (yellow on sheet 1). Today the business has 3 registered users and €2.00 of lifetime revenue. This sheet exists to show the SHAPE the model produces and to be re-run against real numbers later — it is not evidence of anything and must not be presented to an investor as a forecast.
A4: Month | B4: New free signups | C4: New paid | D4: Churned | E4: Active paid | F4: MRR | G4: Creator payouts | H4: API + infra COGS | I4: Stripe fees | J4: Gross profit | K4: Fixed costs | L4: Net profit | M4: Cumulative
A5: 1 | B5: ='1_Inputs'!$B$42 | C5: =B5*'1_Inputs'!$B$43 | D5: ='1_Inputs'!$B$41*'1_Inputs'!$B$44 | E5: ='1_Inputs'!$B$41+C5-D5 | F5: =E5*('1_Inputs'!$B$45*'1_Inputs'!$B$19+'1_Inputs'!$B$46*'1_Inputs'!$B$21+'1_Inputs'!$B$47*'1_Inputs'!$B$23) | G5: =F5*'1_Inputs'!$B$31 | H5: =E5*('1_Inputs'!$B$45*'1_Inputs'!$B$20+'1_Inputs'!$B$46*'1_Inputs'!$B$22+'1_Inputs'!$B$47*'1_Inputs'!$B$24)*'1_Inputs'!$B$48*'1_Inputs'!$B$56+B5*'1_Inputs'!$B$57 | I5: =F5*'1_Inputs'!$B$36+E5*'1_Inputs'!$B$37 | J5: =F5-G5-H5-I5 | K5: ='1_Inputs'!$B$49 | L5: =J5-K5 | M5: =L5
A6: 2 | B6: ='1_Inputs'!$B$42 | C6: =B6*'1_Inputs'!$B$43 | D6: =E5*'1_Inputs'!$B$44 | E6: =E5+C6-D6 | F6: =E6*('1_Inputs'!$B$45*'1_Inputs'!$B$19+'1_Inputs'!$B$46*'1_Inputs'!$B$21+'1_Inputs'!$B$47*'1_Inputs'!$B$23) | G6: =F6*'1_Inputs'!$B$31 | H6: =E6*('1_Inputs'!$B$45*'1_Inputs'!$B$20+'1_Inputs'!$B$46*'1_Inputs'!$B$22+'1_Inputs'!$B$47*'1_Inputs'!$B$24)*'1_Inputs'!$B$48*'1_Inputs'!$B$56+B6*'1_Inputs'!$B$57 | I6: =F6*'1_Inputs'!$B$36+E6*'1_Inputs'!$B$37 | J6: =F6-G6-H6-I6 | K6: ='1_Inputs'!$B$49 | L6: =J6-K6 | M6: =M5+L6
A7: 3 | B7: ='1_Inputs'!$B$42 | C7: =B7*'1_Inputs'!$B$43 | D7: =E6*'1_Inputs'!$B$44 | E7: =E6+C7-D7 | F7: =E7*('1_Inputs'!$B$45*'1_Inputs'!$B$19+'1_Inputs'!$B$46*'1_Inputs'!$B$21+'1_Inputs'!$B$47*'1_Inputs'!$B$23) | G7: =F7*'1_Inputs'!$B$31 | H7: =E7*('1_Inputs'!$B$45*'1_Inputs'!$B$20+'1_Inputs'!$B$46*'1_Inputs'!$B$22+'1_Inputs'!$B$47*'1_Inputs'!$B$24)*'1_Inputs'!$B$48*'1_Inputs'!$B$56+B7*'1_Inputs'!$B$57 | I7: =F7*'1_Inputs'!$B$36+E7*'1_Inputs'!$B$37 | J7: =F7-G7-H7-I7 | K7: ='1_Inputs'!$B$49 | L7: =J7-K7 | M7: =M6+L7
A8: 4 | B8: ='1_Inputs'!$B$42 | C8: =B8*'1_Inputs'!$B$43 | D8: =E7*'1_Inputs'!$B$44 | E8: =E7+C8-D8 | F8: =E8*('1_Inputs'!$B$45*'1_Inputs'!$B$19+'1_Inputs'!$B$46*'1_Inputs'!$B$21+'1_Inputs'!$B$47*'1_Inputs'!$B$23) | G8: =F8*'1_Inputs'!$B$31 | H8: =E8*('1_Inputs'!$B$45*'1_Inputs'!$B$20+'1_Inputs'!$B$46*'1_Inputs'!$B$22+'1_Inputs'!$B$47*'1_Inputs'!$B$24)*'1_Inputs'!$B$48*'1_Inputs'!$B$56+B8*'1_Inputs'!$B$57 | I8: =F8*'1_Inputs'!$B$36+E8*'1_Inputs'!$B$37 | J8: =F8-G8-H8-I8 | K8: ='1_Inputs'!$B$49 | L8: =J8-K8 | M8: =M7+L8
A9: 5 | B9: ='1_Inputs'!$B$42 | C9: =B9*'1_Inputs'!$B$43 | D9: =E8*'1_Inputs'!$B$44 | E9: =E8+C9-D9 | F9: =E9*('1_Inputs'!$B$45*'1_Inputs'!$B$19+'1_Inputs'!$B$46*'1_Inputs'!$B$21+'1_Inputs'!$B$47*'1_Inputs'!$B$23) | G9: =F9*'1_Inputs'!$B$31 | H9: =E9*('1_Inputs'!$B$45*'1_Inputs'!$B$20+'1_Inputs'!$B$46*'1_Inputs'!$B$22+'1_Inputs'!$B$47*'1_Inputs'!$B$24)*'1_Inputs'!$B$48*'1_Inputs'!$B$56+B9*'1_Inputs'!$B$57 | I9: =F9*'1_Inputs'!$B$36+E9*'1_Inputs'!$B$37 | J9: =F9-G9-H9-I9 | K9: ='1_Inputs'!$B$49 | L9: =J9-K9 | M9: =M8+L9
A10: 6 | B10: ='1_Inputs'!$B$42 | C10: =B10*'1_Inputs'!$B$43 | D10: =E9*'1_Inputs'!$B$44 | E10: =E9+C10-D10 | F10: =E10*('1_Inputs'!$B$45*'1_Inputs'!$B$19+'1_Inputs'!$B$46*'1_Inputs'!$B$21+'1_Inputs'!$B$47*'1_Inputs'!$B$23) | G10: =F10*'1_Inputs'!$B$31 | H10: =E10*('1_Inputs'!$B$45*'1_Inputs'!$B$20+'1_Inputs'!$B$46*'1_Inputs'!$B$22+'1_Inputs'!$B$47*'1_Inputs'!$B$24)*'1_Inputs'!$B$48*'1_Inputs'!$B$56+B10*'1_Inputs'!$B$57 | I10: =F10*'1_Inputs'!$B$36+E10*'1_Inputs'!$B$37 | J10: =F10-G10-H10-I10 | K10: ='1_Inputs'!$B$49 | L10: =J10-K10 | M10: =M9+L10
A11: 7 | B11: ='1_Inputs'!$B$42 | C11: =B11*'1_Inputs'!$B$43 | D11: =E10*'1_Inputs'!$B$44 | E11: =E10+C11-D11 | F11: =E11*('1_Inputs'!$B$45*'1_Inputs'!$B$19+'1_Inputs'!$B$46*'1_Inputs'!$B$21+'1_Inputs'!$B$47*'1_Inputs'!$B$23) | G11: =F11*'1_Inputs'!$B$31 | H11: =E11*('1_Inputs'!$B$45*'1_Inputs'!$B$20+'1_Inputs'!$B$46*'1_Inputs'!$B$22+'1_Inputs'!$B$47*'1_Inputs'!$B$24)*'1_Inputs'!$B$48*'1_Inputs'!$B$56+B11*'1_Inputs'!$B$57 | I11: =F11*'1_Inputs'!$B$36+E11*'1_Inputs'!$B$37 | J11: =F11-G11-H11-I11 | K11: ='1_Inputs'!$B$49 | L11: =J11-K11 | M11: =M10+L11
A12: 8 | B12: ='1_Inputs'!$B$42 | C12: =B12*'1_Inputs'!$B$43 | D12: =E11*'1_Inputs'!$B$44 | E12: =E11+C12-D12 | F12: =E12*('1_Inputs'!$B$45*'1_Inputs'!$B$19+'1_Inputs'!$B$46*'1_Inputs'!$B$21+'1_Inputs'!$B$47*'1_Inputs'!$B$23) | G12: =F12*'1_Inputs'!$B$31 | H12: =E12*('1_Inputs'!$B$45*'1_Inputs'!$B$20+'1_Inputs'!$B$46*'1_Inputs'!$B$22+'1_Inputs'!$B$47*'1_Inputs'!$B$24)*'1_Inputs'!$B$48*'1_Inputs'!$B$56+B12*'1_Inputs'!$B$57 | I12: =F12*'1_Inputs'!$B$36+E12*'1_Inputs'!$B$37 | J12: =F12-G12-H12-I12 | K12: ='1_Inputs'!$B$49 | L12: =J12-K12 | M12: =M11+L12
A13: 9 | B13: ='1_Inputs'!$B$42 | C13: =B13*'1_Inputs'!$B$43 | D13: =E12*'1_Inputs'!$B$44 | E13: =E12+C13-D13 | F13: =E13*('1_Inputs'!$B$45*'1_Inputs'!$B$19+'1_Inputs'!$B$46*'1_Inputs'!$B$21+'1_Inputs'!$B$47*'1_Inputs'!$B$23) | G13: =F13*'1_Inputs'!$B$31 | H13: =E13*('1_Inputs'!$B$45*'1_Inputs'!$B$20+'1_Inputs'!$B$46*'1_Inputs'!$B$22+'1_Inputs'!$B$47*'1_Inputs'!$B$24)*'1_Inputs'!$B$48*'1_Inputs'!$B$56+B13*'1_Inputs'!$B$57 | I13: =F13*'1_Inputs'!$B$36+E13*'1_Inputs'!$B$37 | J13: =F13-G13-H13-I13 | K13: ='1_Inputs'!$B$49 | L13: =J13-K13 | M13: =M12+L13
A14: 10 | B14: ='1_Inputs'!$B$42 | C14: =B14*'1_Inputs'!$B$43 | D14: =E13*'1_Inputs'!$B$44 | E14: =E13+C14-D14 | F14: =E14*('1_Inputs'!$B$45*'1_Inputs'!$B$19+'1_Inputs'!$B$46*'1_Inputs'!$B$21+'1_Inputs'!$B$47*'1_Inputs'!$B$23) | G14: =F14*'1_Inputs'!$B$31 | H14: =E14*('1_Inputs'!$B$45*'1_Inputs'!$B$20+'1_Inputs'!$B$46*'1_Inputs'!$B$22+'1_Inputs'!$B$47*'1_Inputs'!$B$24)*'1_Inputs'!$B$48*'1_Inputs'!$B$56+B14*'1_Inputs'!$B$57 | I14: =F14*'1_Inputs'!$B$36+E14*'1_Inputs'!$B$37 | J14: =F14-G14-H14-I14 | K14: ='1_Inputs'!$B$49 | L14: =J14-K14 | M14: =M13+L14
A15: 11 | B15: ='1_Inputs'!$B$42 | C15: =B15*'1_Inputs'!$B$43 | D15: =E14*'1_Inputs'!$B$44 | E15: =E14+C15-D15 | F15: =E15*('1_Inputs'!$B$45*'1_Inputs'!$B$19+'1_Inputs'!$B$46*'1_Inputs'!$B$21+'1_Inputs'!$B$47*'1_Inputs'!$B$23) | G15: =F15*'1_Inputs'!$B$31 | H15: =E15*('1_Inputs'!$B$45*'1_Inputs'!$B$20+'1_Inputs'!$B$46*'1_Inputs'!$B$22+'1_Inputs'!$B$47*'1_Inputs'!$B$24)*'1_Inputs'!$B$48*'1_Inputs'!$B$56+B15*'1_Inputs'!$B$57 | I15: =F15*'1_Inputs'!$B$36+E15*'1_Inputs'!$B$37 | J15: =F15-G15-H15-I15 | K15: ='1_Inputs'!$B$49 | L15: =J15-K15 | M15: =M14+L15
A16: 12 | B16: ='1_Inputs'!$B$42 | C16: =B16*'1_Inputs'!$B$43 | D16: =E15*'1_Inputs'!$B$44 | E16: =E15+C16-D16 | F16: =E16*('1_Inputs'!$B$45*'1_Inputs'!$B$19+'1_Inputs'!$B$46*'1_Inputs'!$B$21+'1_Inputs'!$B$47*'1_Inputs'!$B$23) | G16: =F16*'1_Inputs'!$B$31 | H16: =E16*('1_Inputs'!$B$45*'1_Inputs'!$B$20+'1_Inputs'!$B$46*'1_Inputs'!$B$22+'1_Inputs'!$B$47*'1_Inputs'!$B$24)*'1_Inputs'!$B$48*'1_Inputs'!$B$56+B16*'1_Inputs'!$B$57 | I16: =F16*'1_Inputs'!$B$36+E16*'1_Inputs'!$B$37 | J16: =F16-G16-H16-I16 | K16: ='1_Inputs'!$B$49 | L16: =J16-K16 | M16: =M15+L16
A17: 13 | B17: ='1_Inputs'!$B$42 | C17: =B17*'1_Inputs'!$B$43 | D17: =E16*'1_Inputs'!$B$44 | E17: =E16+C17-D17 | F17: =E17*('1_Inputs'!$B$45*'1_Inputs'!$B$19+'1_Inputs'!$B$46*'1_Inputs'!$B$21+'1_Inputs'!$B$47*'1_Inputs'!$B$23) | G17: =F17*'1_Inputs'!$B$31 | H17: =E17*('1_Inputs'!$B$45*'1_Inputs'!$B$20+'1_Inputs'!$B$46*'1_Inputs'!$B$22+'1_Inputs'!$B$47*'1_Inputs'!$B$24)*'1_Inputs'!$B$48*'1_Inputs'!$B$56+B17*'1_Inputs'!$B$57 | I17: =F17*'1_Inputs'!$B$36+E17*'1_Inputs'!$B$37 | J17: =F17-G17-H17-I17 | K17: ='1_Inputs'!$B$49 | L17: =J17-K17 | M17: =M16+L17
... A40: 36 | B40: ='1_Inputs'!$B$42 | C40: =B40*'1_Inputs'!$B$43 | D40: =E39*'1_Inputs'!$B$44 | E40: =E39+C40-D40 | F40: =E40*('1_Inputs'!$B$45*'1_Inputs'!$B$19+'1_Inputs'!$B$46*'1_Inputs'!$B$21+'1_Inputs'!$B$47*'1_Inputs'!$B$23) | G40: =F40*'1_Inputs'!$B$31 | H40: =E40*('1_Inputs'!$B$45*'1_Inputs'!$B$20+'1_Inputs'!$B$46*'1_Inputs'!$B$22+'1_Inputs'!$B$47*'1_Inputs'!$B$24)*'1_Inputs'!$B$48*'1_Inputs'!$B$56+B40*'1_Inputs'!$B$57 | I40: =F40*'1_Inputs'!$B$36+E40*'1_Inputs'!$B$37 | J40: =F40-G40-H40-I40 | K40: ='1_Inputs'!$B$49 | L40: =J40-K40 | M40: =M39+L40
A42: Read the 'Net profit' and 'Cumulative' columns. If they are negative and getting more negative as the member count grows, the pricing is upside-down — that is the sheet-3 finding showing up over time. Fix the pricing on sheet 4 first; only then is a projection worth arguing about.

Sheet 6_Scenarios
A1: SCENARIOS — the three utilisation worlds
A2: Utilisation (what share of granted credits members actually burn) is the variable that decides whether this business works. These three columns hold everything else constant and move only that. Change the utilisation cell on sheet 1 to make the rest of the model follow any of these.
A4: PLATFORM NET PER PROFESSIONAL MEMBER PER MONTH
A5: Scenario | B5: Utilisation | C5: Platform net / member | D5: Annualised per 100 members | E5: Reading
A6: Light — members barely use their credits | B6: 0.1 | C6: ='1_Inputs'!$B$23*(1-'1_Inputs'!$B$31)-('1_Inputs'!$B$23*'1_Inputs'!$B$36+'1_Inputs'!$B$37)-'1_Inputs'!$B$24*B6*'1_Inputs'!$B$56 | D6: =C6*100*12 | E6: Members forget they subscribed. Profitable, but this is churn waiting to happen: nobody renews a product they do not use.
A7: Base — moderate engagement | B7: 0.35 | C7: ='1_Inputs'!$B$23*(1-'1_Inputs'!$B$31)-('1_Inputs'!$B$23*'1_Inputs'!$B$36+'1_Inputs'!$B$37)-'1_Inputs'!$B$24*B7*'1_Inputs'!$B$56 | D7: =C7*100*12 | E7: The utilisation figure currently on sheet 1. This is the case that has to work.
A8: Heavy — engaged members using the product | B8: 0.8 | C8: ='1_Inputs'!$B$23*(1-'1_Inputs'!$B$31)-('1_Inputs'!$B$23*'1_Inputs'!$B$36+'1_Inputs'!$B$37)-'1_Inputs'!$B$24*B8*'1_Inputs'!$B$56 | D8: =C8*100*12 | E8: The outcome a marketplace actually wants. Under today's pricing it is the most expensive outcome for us — which is the clearest possible statement that the pricing is inverted.
A10: THE SAME THREE SCENARIOS UNDER FIX 1 (creators paid on NET)
A11: Scenario | B11: Utilisation | C11: Platform net / member | D11: Annualised per 100 members | E11: Reading
A12: Light — members barely use their credits | B12: 0.1 | C12: =('1_Inputs'!$B$23-'1_Inputs'!$B$24*B12*'1_Inputs'!$B$56-('1_Inputs'!$B$23*'1_Inputs'!$B$36+'1_Inputs'!$B$37))*(1-'1_Inputs'!$B$31) | D12: =C12*100*12 | E12: Positive in every scenario. Smaller in absolute terms at high usage — but never negative.
A13: Base — moderate engagement | B13: 0.35 | C13: =('1_Inputs'!$B$23-'1_Inputs'!$B$24*B13*'1_Inputs'!$B$56-('1_Inputs'!$B$23*'1_Inputs'!$B$36+'1_Inputs'!$B$37))*(1-'1_Inputs'!$B$31) | D13: =C13*100*12 | E13: Positive in every scenario. Smaller in absolute terms at high usage — but never negative.
A14: Heavy — engaged members using the product | B14: 0.8 | C14: =('1_Inputs'!$B$23-'1_Inputs'!$B$24*B14*'1_Inputs'!$B$56-('1_Inputs'!$B$23*'1_Inputs'!$B$36+'1_Inputs'!$B$37))*(1-'1_Inputs'!$B$31) | D14: =C14*100*12 | E14: Positive in every scenario. Smaller in absolute terms at high usage — but never negative.

Sheet 7_Executive Summary
A1: EXECUTIVE SUMMARY — read this screen only
A2: Everything below is calculated from the live code and the assumptions on sheet 1. Nothing here is typed in by hand.
A4: THE FOUR NUMBERS THAT MATTER
A5: Question | B5: Answer | C5: Unit | D5: What it means
A6: What does one hosted-agent call cost us? | B6: ='1_Inputs'!$B$55 | C6: EUR | D6: LLM tokens plus serverless compute. The whole model rests on this and on the two token assumptions behind it — measure them first.
A7: What must one credit sell for, just to break even? | B7: =IFERROR('1_Inputs'!$B$56/('1_Inputs'!$B$30-'1_Inputs'!$B$36),0) | C7: EUR | D7: Because we keep only 15% of revenue, Stripe takes 1.5%, and the whole API bill comes out of what is left.
A8: What does the Professional tier actually sell a credit for? | B8: ='1_Inputs'!$B$23/'1_Inputs'!$B$24 | C8: EUR | D8: €99 for 8,000 credits. Compare with the row above.
A9: Above what usage does a Professional member lose us money? | B9: =IFERROR(('1_Inputs'!$B$23*(1-'1_Inputs'!$B$31)-('1_Inputs'!$B$23*'1_Inputs'!$B$36+'1_Inputs'!$B$37))/('1_Inputs'!$B$24*'1_Inputs'!$B$56),0) | C9: % of credits | D9: Share of their granted credits. Above this line, the better the product performs, the more we lose.
A11: THE FINDING
A12: Agently currently pays creators 85% of GROSS membership revenue while absorbing 100% of the Anthropic API cost out of the remaining 15%. That makes gross margin a function of how much customers use the product — in the wrong direction. Past a low usage threshold, every additional call costs the platform money, and the most expensive tier crosses that threshold soonest, because it grants the most credits per euro. This is not a scale problem and it does not improve with volume: it is arithmetic. The fix is on sheet 4, and it is small — pay creators a share of revenue NET of the API cost of serving their agents, rather than gross. The creator's incentive is unchanged (more usage still means more money), and the platform can no longer be bankrupted by its own success.
A14: WHAT THIS MODEL IS NOT
A15: It is not evidence of a market. As of the live database query on 6.9.2026 the platform has 2 approved agents, 0 external creators, 3 registered users and €2.00 of lifetime revenue. Sheets 1–4 are decision-grade: they run on real code and real published prices, and they are enough to fix the pricing today. Sheets 5–6 are scaffolding built on invented growth assumptions and should not be shown to an investor as a forecast — they become real when there are real cohorts to put in them.
A17: NEXT THREE ACTIONS
A18: 1. Log the real input and output token counts from the Anthropic response on every hosted call. Two numbers, one commit — they replace the only two load-bearing assumptions in this model.
A19: 2. Decide between Fix 1 (pay creators on net) and Fix 2 (reprice credits) on sheet 4. Fix 1 is recommended.
A20: 3. Re-run this model with the measured token counts before any pricing goes public or any investor sees a number.

Sheet 8_Sources
A1: SOURCES & PROVENANCE
A2: House rule: never fabricate. Every input in this model is listed here with where it came from. Anything marked ASSUMPTION is a placeholder and is flagged as such wherever it appears.
A4: Input | B4: Status | C4: Source
A5: LLM the invoke route calls | B5: MEASURED | C5: app/api/hosted-agents/[slug]/invoke/route.ts:258 — read from the live code, not assumed.
A6: Input price per 1M tokens (USD) | B6: SOURCED | C6: Anthropic published API pricing for claude-sonnet-5. Verify at anthropic.com/pricing before investor use.
A7: Output price per 1M tokens (USD) | B7: SOURCED | C7: Anthropic published API pricing for claude-sonnet-5. Verify at anthropic.com/pricing before investor use.
A8: USD → EUR conversion rate | B8: ASSUMPTION | C8: Placeholder. Replace with the rate your Stripe/bank actually settles at.
A9: max_tokens cap per call | B9: MEASURED | C9: app/api/hosted-agents/[slug]/invoke/route.ts:259 — hard ceiling on output per call.
A10: Average INPUT tokens per call | B10: ASSUMPTION | C10: Hidden agent system prompt + user input. NOT measured — log real token counts from the Anthropic response usage object and replace this. This is the single most important number in the model.
A11: Average OUTPUT tokens per call | B11: ASSUMPTION | C11: Assumed well below the 2048 cap. NOT measured — same fix as above: log response.usage.output_tokens.
A12: Non-LLM infra cost per call (Vercel, Supabase) | B12: ASSUMPTION | C12: Serverless function + DB writes per invocation. Small but non-zero. Replace with real Vercel/Supabase billing divided by call count once there is volume.
A13: Basic tier — monthly price | B13: MEASURED | C13: lib/membership.ts MEMBERSHIP_TIERS.basic.monthlyPriceCents = 900. Code comment calls it a placeholder.
A14: Basic tier — monthly credits granted | B14: MEASURED | C14: lib/membership.ts. Code comment: 'Round, clearly-arbitrary numbers... not measured against any real per-call cost.' This model exists to fix exactly that.
A15: Pro tier — monthly price | B15: MEASURED | C15: lib/membership.ts monthlyPriceCents = 2900.
... A21: Platform fee — share WE keep | B21: MEASURED | C21: lib/membership.ts PLATFORM_FEE_PERCENT = 15. Report ch.6: 'start low (10-15%), raise once there's liquidity.'
A22: Creator share — share THEY get | B22: MEASURED | C22: =1 − platform fee. lib/creator-payouts.ts pools 85% of membership revenue and splits it by usage share.
A23: Creator payout is calculated on… | B23: MEASURED | C23: lib/creator-payouts.ts: poolCents = totalRevenueCents × 85%. API cost is NOT deducted first. See sheet 4 — this is the structural problem.
A24: Stripe percentage fee (EU cards) | B24: SOURCED | C24: Stripe published EU standard rate ~1.5%. Verify against your own Stripe dashboard.
A25: Stripe fixed fee per charge | B25: MEASURED | C25: lib/membership.ts comment: measured at ~€0.25-0.30 by running a live €1 test purchase and reading the resulting Stripe balance transactions — platform ended at -€0.13 net on it.
A26: Paying members at month 0 | B26: MEASURED | C26: Live Supabase query 6.9.2026 — and both are David's own test accounts, not external customers.
A27: New free signups per month | B27: ASSUMPTION | C27: No basis in real data. There are 3 registered users total today. Placeholder to make the sheet compute.
A28: Free → paid conversion rate | B28: ASSUMPTION | C28: Typical prosumer SaaS freemium conversion is low single digits. Not measured for this product.
A29: Monthly churn of paying members | B29: ASSUMPTION | C29: Placeholder in the normal SMB/prosumer range. Not measured — there is no cohort history yet.
A30: Tier mix — Basic | B30: ASSUMPTION | C30: Placeholder. No real mix data exists.
A31: Tier mix — Pro | B31: ASSUMPTION | C31: Placeholder.
A32: Tier mix — Professional | B32: ASSUMPTION | C32: Placeholder.
A33: Credit utilisation — % of granted credits actually used | B33: ASSUMPTION | C33: THE swing variable. At low utilisation the model works; above the break-even on sheet 3 every member loses money. Must be measured from agently_agent_invocations as soon as there is real usage.
A34: Fixed monthly operating cost | B34: ASSUMPTION | C34: Vercel + Supabase + domain + email. Excludes any salary for David.
A36: EXTERNAL PRECEDENT — what other platforms actually do (researched 10.9.2026, sources below)
A37: Poe (Quora) | B37: SOURCED | C37: The closest structural analogue to our hosted model — and it deliberately ABANDONED the usage-pool split. Creators now set a price per message themselves, up to $10,000 per 1,000 messages, precisely because a pool does not cover an expensive bot's inference cost. That is the same failure this model found, reached independently by a company that raised $75M from a16z to run it. [TechCrunch 9.4.2024 techcrunch.com/2024/04/09/poe-introduces-a-price-per-message-revenue-model-for-ai-bot-creators/ · poe.com/blog/new-on-poe-creator-monetization-via-price-per-message · a16z round: TechCrunch 9.1.2024]
A38: OpenAI GPT Store | B38: SOURCED | C38: Our payout design was described as 'the same model the GPT Store pays creators under'. That claim does not hold up: revenue sharing was announced Jan 2024, never opened beyond an invite-only US pilot, the formula was never published, and GPTs have since been superseded by the Apps SDK — whose documented monetization route is external checkout on the developer's own site. CORRECT THIS CLAIM wherever it appears. [VentureBeat 1.2024 · OpenAI dev community thread 839172 · developers.openai.com/apps-sdk/build/monetization]
A39: Take rates, observed range | B39: SOURCED | C39: Apple 30% (15% under $1M) · Google Play 15% on subs · Unity Asset Store 30% · Shopify 0% on first $1M · Patreon 10% · Substack 10% · YouTube 45% of ad revenue. Our 15% is defensible and creator-friendly, but it is NOT 'standard' — the modal digital-goods rate is 30%. Reframe the claim. [Apple SBP via RevenueCat · assetstore.unity.com/publishing · TechCrunch 29.6.2021 (Shopify) · support.google.com/youtube/answer/72902]
A40: Monthly payout cadence | B40: SOURCED | C40: This half of our claim does hold — Patreon, Substack and YouTube all pay monthly. Note that every mature system also has a minimum payout threshold and a lag (Roblox 30,000 Robux, YouTube $100). Ours has neither yet; investors will ask. [support.google.com/youtube/answer/72902 · create.roblox.com/docs/production/monetization/developer-exchange]
A41: Disintermediation risk | B41: SOURCED | C41: Peer-reviewed result: as a platform improves trust between its two sides, it increases the risk they transact off-platform to avoid the fee. Directly relevant to file agents, which have zero ongoing platform dependency once downloaded. The hosted product is the only half with a real anti-leakage mechanism. [Hagiu & Wright, 'Marketplace Leakage', Management Science — doi 10.1287/mnsc.2023.4757]
A43: NOT CONFIRMED — do not present as fact
A44: Real input/output token counts per hosted call — never measured. The two most important numbers in the model.
A45: Real credit utilisation — never measured; there is no meaningful usage history.
A46: Stripe's exact effective rate on this account — the €0.25 fixed fee is measured, the 1.5% is the published rate.
A47: USD/EUR rate actually realised after bank spread.
A48: Every growth input on sheet 5 (signups, conversion, churn, tier mix) — invented placeholders.
